---
title: 第 8 章：错误、调试和测试
---

## 8.0.简介

**错误**

- 程序编写有问题，如『本来应该输出整数结果输出了字符串』
- 用户使用上使得程序出现了问题，如『让用户输入email地址，结果得到一个空字符串』，这种错误可以通过检查用户输入来做相应的处理
- 还有一类错误是完全无法在程序运行过程中预测的，比如写入文件的时候，磁盘满了，写不进去了，或者从网络抓取数据，网络突然断掉了。这类错误也称为异常，在程序中通常是必须处理的，否则，程序会因为各种问题终止并退出

Python内置了一套异常处理机制，来帮助我们进行错误处理。

**调试**

- 此外，我们也需要跟踪程序的执行，查看变量的值是否正确，这个过程称为『调试』
- Python 的 `pdb` 模块可以让我们以单步方式执行代码

**测试**

- 编写测试也很重要，有了良好的测试，就可以在程序修改后反复运行，确保程序输出符合我们编写的测试

<br></br>

## 8.1.错误处理

### `try` 的基本用法

---

**举例 1：**

``` python
try:
    print('try...')
    r = 10 / 0
    print('result:', r)
except ZeroDivisionError as e:
    print('except:', e)
finally:
    print('finally...')
print('END')
```

``` bash
try...
except: division by zero
finally...
END
```

**举例 2：**

上面的代码在计算 `10 / 0` 时会产生一个除法运算错误，如果把除数 `0` 改成 `2`

``` bash
try...
result: 5
finally...
END
```

由于没有错误发生，所以 `except` 语句块不会被执行，但是 `finally` 如果有，则一定会被执行（可以没有 `finally` 语句）。

**举例 3：**

可以有**多个** `except` 来捕获不同类型的错误：

``` python 
try:
    print('try...')
    r = 10 / int('a')
    print('result:', r)
except ValueError as e:
    print('ValueError:', e)
except ZeroDivisionError as e:
    print('ZeroDivisionError:', e)
finally:
    print('finally...')
print('END')
```

``` bash
try...
ValueError: invalid literal for int() with base 10: 'a'
finally...
END
```

**举例 4：**

如果没有错误发生，可以在 `except` 语句块后面加一个 `else` ，当没有错误发生时，会自动执行 `else` 语句

``` python
try:
    print('try...')
    r = 10 / int('2')
    print('result:', r)
except ValueError as e:
    print('ValueError:', e)
except ZeroDivisionError as e:
    print('ZeroDivisionError:', e)
else:
    print('no error!')
finally:
    print('finally...')
print('END')
```

``` bash
try...
result: 5.0
no error!
finally...
END
```

### 错误继承

---

Python 的错误其实也是 `class`，所有的错误类型都继承自 `BaseException`，所以在使用 `except` 时需要注意的是，它不但捕获该类型的错误，还把其子类也“一网打尽”。比如：

``` python
try:
    foo()
except ValueError as e:
    print('ValueError')
except UnicodeError as e:
    print('UnicodeError')
```

第二个 `except `永远也捕获不到 `UnicodeError`，因为 `UnicodeError` 是 `ValueError` 的子类，如果有，也被第一个 `except` 给捕获了。

### 跨越多层调用

---

使用 `try...except` 捕获错误还有一个巨大的好处，就是可以**跨越多层调用**，比如函数 `main()` 调用 `bar()`，`bar()` 调用 `foo()`，结果 `foo()` 出错了，这时，只要 `main()` 捕获到了，就可以处理：

``` python
def foo(s):
    return 10 / int(s)


def bar(s):
    return foo(s) * 2


def main():
    try:
        bar('0')
    except Exception as e:
        print('Error:', e)
    finally:
        print('finally...')
```

``` bash
>>> main()
Error: division by zero
finally...
```

### 调用栈

---

``` python
def foo(s):
    return 10 / int(s)


def bar(s):
    return foo(s) * 2


def main():
    bar('0')


main()
```

``` bash
$ python3 err.py
Traceback (most recent call last):
  File "err.py", line 11, in <module>
    main()
  File "err.py", line 9, in main
    bar('0')
  File "err.py", line 6, in bar
    return foo(s) * 2
  File "err.py", line 3, in foo
    return 10 / int(s)
ZeroDivisionError: division by zero
```

::: warning
出错的时候，一定要分析错误的调用栈信息，才能定位错误的位置。
:::

### 记录错误

---

如果不捕获错误，自然可以让 Python 解释器来打印出错误堆栈，但程序也被结束了。既然我们能捕获错误，就可以把错误堆栈打印出来，然后分析错误原因，同时，让程序继续执行下去。

Python 内置的 `logging` 模块可以非常容易地记录错误信息：

``` python
import logging


def foo(s):
    return 10 / int(s)


def bar(s):
    return foo(s) * 2


def main():
    try:
        bar('0')
    except Exception as e:
        logging.exception(e)


main()
print('END')
```

``` bash
$ python3 err_logging.py
ERROR:root:division by zero
Traceback (most recent call last):
  File "err_logging.py", line 13, in main
    bar('0')
  File "err_logging.py", line 9, in bar
    return foo(s) * 2
  File "err_logging.py", line 6, in foo
    return 10 / int(s)
ZeroDivisionError: division by zero
END
```
同样是出错，但程序打印完错误信息后会继续执行，并正常退出。

通过配置，`logging` 还可以把错误记录到日志文件里，方便事后排查。

### 抛出错误

---

**举例 1：**

``` python 
class FooError(ValueError):
    pass


def foo(s):
    n = int(s)
    if n==0:
        raise FooError('invalid value: %s' % s)
    return 10 / n


foo('0')
```

``` bash
$ python3 err_raise.py 
Traceback (most recent call last):
  File "err_throw.py", line 11, in <module>
    foo('0')
  File "err_throw.py", line 8, in foo
    raise FooError('invalid value: %s' % s)
__main__.FooError: invalid value: 0
```

**举例 2：**

::: warning
只有在必要的时候才定义我们自己的错误类型。如果可以选择 Python 已有的内置的错误类型（比如 `ValueError`，`TypeError`），尽量使用 Python 内置的错误类型。
:::

``` python
def foo(s):
    n = int(s)
    if n==0:
        raise ValueError('invalid value: %s' % s)
    return 10 / n


def bar():
    try:
        foo('0')
    except ValueError as e:
        print('ValueError!')
        raise


bar()
```

``` bash
ValueError!
Traceback (most recent call last):
  File "<stdin>", line 1, in <module>
  File "<stdin>", line 3, in bar
  File "<stdin>", line 4, in foo
ValueError: invalid value: 0
```

::: tip
捕获并打印错误后，又用 `raise` 语句抛出，这样的作法相当常见。
:::

**举例 3：**

``` python
try:
    10 / 0
except ZeroDivisionError:
    raise ValueError('input error!')
```

`raise` 语句如果不带参数，就会把当前错误原样抛出。此外，如上述例子，在 `except` 中 `raise` 一个 Error，还可以把一种类型的错误转化成另一种类型，只要是合理的转换逻辑就可以，但是，决不应该把一个`IOError` 转换成毫不相干的 `ValueError`。


### 小结

---

使用 `raise` 主动抛出异常和错误的意义在于 —— 如果有大量错误出现，我们可以把精力集中在我们所关注的、迫切需要解决的错误上。

<br></br>

## 8.2.调试

### 打印变量

---

代码冗长，后续需要删除所有无关的 `print` 语句，不推荐。 :x:

### 断言

---

凡是用 `print()` 来辅助查看的地方，都可以用断言（`assert`）来替代：

``` python
assert expression [, arguments]

# 等价于

if not expression:
    raise AssertionError(arguments)
```

使用实例：

``` python
def foo(s):
    n = int(s)
    assert n != 0, 'n is zero!'
    return 10 / n


def main():
    foo('0')
```

``` bash
$ python err.py
Traceback (most recent call last):
  ...
AssertionError: n is zero!
```

### logging

---

把 `print()` 替换为 `logging` 是第 3 种方式，和 `assert` 比，`logging` 不会抛出错误，而且可以输出到文件：

``` python
import logging

s = '0'
n = int(s)
logging.info('n = %d' % n)
print(10 / n)
```

通过设置可以输出不同级别 (`DEBUG`, `INFO`, `WARNING`, `ERROR`) 的信息：

```python
import logging
logging.basicConfig(level=logging.INFO)
```

`logging` 的另一个好处是通过简单的配置，一条语句可以同时输出到不同的地方，比如 console 和文件。

`logging` 在实际生产环境中起着很大的作用。

### `pdb` 和 IDE

---

不多做阐述。

### 小结

---

- 不推荐使用 `print` 调试程序
- 简单的调试，可以用断言 `assert`
- IDE 有强大的调试功能
- 实际生产环境中，`logging` 才是终极武器

<br></br>

## 8.3.单元测试

### 使用示例

---

单元测试是用来对一个模块、一个函数或者一个类来进行正确性检验的测试工作。

比如对函数 `abs()`，我们可以编写出以下几个测试用例：

- 输入正数，比如 `1`、`1.2`、`0.99`，期待返回值与输入相同；
- 输入负数，比如 `-1`、`-1.2`、`-0.99`，期待返回值与输入相反；
- 输入 `0`，期待返回 `0`；
- 输入非数值类型，比如`None`、`[]`、`{}`，期待抛出 `TypeError`。

把上面的测试用例放到一个测试模块里，就是一个完整的单元测试。

``` python
class Student(object):

    def __init__(self, name, score):
        self.name = name
        self.score = score

    def get_grade(self):
        if self.score < 0 or self.score > 100:
            raise ValueError
        if self.score >= 80:
            return 'A'
        if self.score >= 60:
            return 'B'
        return 'C'
```

``` python
class TestStudent(unittest.TestCase):

    def test_80_to_100(self):
        s1 = Student('Bart', 80)
        s2 = Student('Lisa', 100)
        self.assertEqual(s1.get_grade(), 'A')  # 断言输出是否符合预期
        self.assertEqual(s2.get_grade(), 'A')

    def test_60_to_80(self):
        s1 = Student('Bart', 60)
        s2 = Student('Lisa', 79)
        self.assertEqual(s1.get_grade(), 'B')
        self.assertEqual(s2.get_grade(), 'B')

    def test_0_to_60(self):
        s1 = Student('Bart', 0)
        s2 = Student('Lisa', 59)
        self.assertEqual(s1.get_grade(), 'C')
        self.assertEqual(s2.get_grade(), 'C')

    def test_invalid(self):
        s1 = Student('Bart', -1)
        s2 = Student('Lisa', 101)
        with self.assertRaises(ValueError):  # 断言错误类型
            s1.get_grade()
        with self.assertRaises(ValueError):
            s2.get_grade()


if __name__ == '__main__':
    unittest.main()
```

``` bash
$ python -m unittest student_test
# 或者 python student_test.py，即当作脚本运行
.....
----------------------------------------------------------------------
Ran 5 tests in 0.000s

OK
```

推荐 `python -m unittest student_test` 的方法，因为这样可以一次批量运行很多单元测试，并且有很多工具可以自动来运行这些单元测试。

### setUP 和 tearDown

---

可以在单元测试中编写两个特殊的 `setUp()` 和 `tearDown()` 方法。这两个方法会分别在每调用一个测试方法的前后分别被执行。

`setUp()` 和 `tearDown()` 方法有什么用呢？设想你的测试需要启动一个数据库，这时，就可以在 `setUp()` 方法中连接数据库，在 `tearDown()` 方法中关闭数据库，这样，不必在每个测试方法中重复相同的代码：

``` python
class TestDict(unittest.TestCase):

    def setUp(self):
        print('setUp...')

    def tearDown(self):
        print('tearDown...')
```

可以再次运行测试看看每个测试方法调用前后是否会打印出 `setUp...` 和 `tearDown...`

### 小结

---

[这篇文章](https://www.zhihu.com/question/28729261/answer/1058317111)很好地讲明了单元测试的 what, why, where 以及 how。

<br></br>

## 8.4.文档测试

`doctest` 非常有用，不但可以用来**测试**，还可以直接作为**示例代码**。

通过某些文档生成工具，就可以自动把包含 doctest 的注释提取出来。

``` python
# mydict2.py
class Dict(dict):
    '''
    Simple dict but also support access as x.y style.

    >>> d1 = Dict()
    >>> d1['x'] = 100
    >>> d1.x
    100
    >>> d1.y = 200
    >>> d1['y']
    200
    >>> d2 = Dict(a=1, b=2, c='3')
    >>> d2.c
    '3'
    >>> d2['empty']
    Traceback (most recent call last):
        ...
    KeyError: 'empty'
    >>> d2.empty
    Traceback (most recent call last):
        ...
    AttributeError: 'Dict' object has no attribute 'empty'
    '''
    def __init__(self, **kw):
        super(Dict, self).__init__(**kw)

    def __getattr__(self, key):
        try:
            return self[key]
        except KeyError:
            raise AttributeError(r"'Dict' object has no attribute '%s'" % key)

    def __setattr__(self, key, value):
        self[key] = value


if __name__=='__main__':
    import doctest
    doctest.testmod()
```

Python内置的“文档测试”（`doctest`）模块可以直接提取注释中的代码并执行测试。

`doctest` 严格按照 Python 交互式命令行的输入和输出来判断测试结果是否正确。只有测试异常的时候，可以用 `...` 表示中间一大段烦人的输出。

如果什么输出也没有，则说明我们编写的 doctest 运行都是正确的。
